2018-09-14 19:48:18,138 - INFO - Бот запускается
2018-09-14 19:48:19,306 - WARNING - Retrying (Retry(total=2, connect=None, read=None, redirect=None)) after connection broken by 'NewConnectionError('<telegram.vendor.ptb_urllib3.urllib3.contrib.socks.SOCKSHTTPSConnection object at 0x11062a7f0>: Failed to establish a new connection: 0x02: Connection not allowed by ruleset',)': /bot646613110:AAEaqvqJnNUOqVNNFTmHU5mTEVxN3VJpQlo/deleteWebhook
2018-09-14 19:48:19,577 - WARNING - Retrying (Retry(total=1, connect=None, read=None, redirect=None)) after connection broken by 'NewConnectionError('<telegram.vendor.ptb_urllib3.urllib3.contrib.socks.SOCKSHTTPSConnection object at 0x11062af28>: Failed to establish a new connection: 0x02: Connection not allowed by ruleset',)': /bot646613110:AAEaqvqJnNUOqVNNFTmHU5mTEVxN3VJpQlo/deleteWebhook
2018-09-14 19:48:19,865 - WARNING - Retrying (Retry(total=0, connect=None, read=None, redirect=None)) after connection broken by 'NewConnectionError('<telegram.vendor.ptb_urllib3.urllib3.contrib.socks.SOCKSHTTPSConnection object at 0x11064b048>: Failed to establish a new connection: 0x02: Connection not allowed by ruleset',)': /bot646613110:AAEaqvqJnNUOqVNNFTmHU5mTEVxN3VJpQlo/deleteWebhook
2018-09-14 19:48:20,150 - ERROR - Error while bootstrap del webhook: urllib3 HTTPError SOCKSHTTPSConnectionPool(host='api.telegram.org', port=443): Max retries exceeded with url: /bot646613110:AAEaqvqJnNUOqVNNFTmHU5mTEVxN3VJpQlo/deleteWebhook (Caused by NewConnectionError('<telegram.vendor.ptb_urllib3.urllib3.contrib.socks.SOCKSHTTPSConnection object at 0x11064b438>: Failed to establish a new connection: 0x02: Connection not allowed by ruleset',))
2018-09-14 19:48:20,150 - WARNING - Failed bootstrap phase; try=1 max_retries=-1
2018-09-14 19:48:27,941 - WARNING - Retrying (Retry(total=2, connect=None, read=None, redirect=None)) after connection broken by 'NewConnectionError('<telegram.vendor.ptb_urllib3.urllib3.contrib.socks.SOCKSHTTPSConnection object at 0x11064b630>: Failed to establish a new connection: 0x02: Connection not allowed by ruleset',)': /bot646613110:AAEaqvqJnNUOqVNNFTmHU5mTEVxN3VJpQlo/deleteWebhook
2018-09-14 19:48:28,227 - WARNING - Retrying (Retry(total=1, connect=None, read=None, redirect=None)) after connection broken by 'NewConnectionError('<telegram.vendor.ptb_urllib3.urllib3.contrib.socks.SOCKSHTTPSConnection object at 0x11064b978>: Failed to establish a new connection: 0x02: Connection not allowed by ruleset',)': /bot646613110:AAEaqvqJnNUOqVNNFTmHU5mTEVxN3VJpQlo/deleteWebhook
2018-09-14 19:48:28,583 - WARNING - Retrying (Retry(total=0, connect=None, read=None, redirect=None)) after connection broken by 'NewConnectionError('<telegram.vendor.ptb_urllib3.urllib3.contrib.socks.SOCKSHTTPSConnection object at 0x11064ba58>: Failed to establish a new connection: 0x02: Connection not allowed by ruleset',)': /bot646613110:AAEaqvqJnNUOqVNNFTmHU5mTEVxN3VJpQlo/deleteWebhook
2018-09-14 19:48:28,883 - ERROR - Error while bootstrap del webhook: urllib3 HTTPError SOCKSHTTPSConnectionPool(host='api.telegram.org', port=443): Max retries exceeded with url: /bot646613110:AAEaqvqJnNUOqVNNFTmHU5mTEVxN3VJpQlo/deleteWebhook (Caused by NewConnectionError('<telegram.vendor.ptb_urllib3.urllib3.contrib.socks.SOCKSHTTPSConnection object at 0x11064bc88>: Failed to establish a new connection: 0x02: Connection not allowed by ruleset',))
2018-09-14 19:48:28,883 - WARNING - Failed bootstrap phase; try=2 max_retries=-1
2018-09-14 19:48:40,462 - WARNING - Retrying (Retry(total=2, connect=None, read=None, redirect=None)) after connection broken by 'NewConnectionError('<telegram.vendor.ptb_urllib3.urllib3.contrib.socks.SOCKSHTTPSConnection object at 0x11064b748>: Failed to establish a new connection: 0x02: Connection not allowed by ruleset',)': /bot646613110:AAEaqvqJnNUOqVNNFTmHU5mTEVxN3VJpQlo/deleteWebhook
2018-09-14 19:48:40,748 - WARNING - Retrying (Retry(total=1, connect=None, read=None, redirect=None)) after connection broken by 'NewConnectionError('<telegram.vendor.ptb_urllib3.urllib3.contrib.socks.SOCKSHTTPSConnection object at 0x11064b400>: Failed to establish a new connection: 0x02: Connection not allowed by ruleset',)': /bot646613110:AAEaqvqJnNUOqVNNFTmHU5mTEVxN3VJpQlo/deleteWebhook
2018-09-14 19:48:41,034 - WARNING - Retrying (Retry(total=0, connect=None, read=None, redirect=None)) after connection broken by 'NewConnectionError('<telegram.vendor.ptb_urllib3.urllib3.contrib.socks.SOCKSHTTPSConnection object at 0x11064b470>: Failed to establish a new connection: 0x02: Connection not allowed by ruleset',)': /bot646613110:AAEaqvqJnNUOqVNNFTmHU5mTEVxN3VJpQlo/deleteWebhook
2018-09-14 19:48:41,322 - ERROR - Error while bootstrap del webhook: urllib3 HTTPError SOCKSHTTPSConnectionPool(host='api.telegram.org', port=443): Max retries exceeded with url: /bot646613110:AAEaqvqJnNUOqVNNFTmHU5mTEVxN3VJpQlo/deleteWebhook (Caused by NewConnectionError('<telegram.vendor.ptb_urllib3.urllib3.contrib.socks.SOCKSHTTPSConnection object at 0x11064b358>: Failed to establish a new connection: 0x02: Connection not allowed by ruleset',))
2018-09-14 19:48:41,322 - WARNING - Failed bootstrap phase; try=3 max_retries=-1
2018-09-14 19:48:51,758 - INFO - Received signal 2 (SIGINT), stopping...
2018-09-14 19:48:57,629 - WARNING - Exiting immediately!
2018-09-14 19:48:59,397 - INFO - Бот запускается
2018-09-14 19:48:59,667 - WARNING - Retrying (Retry(total=2, connect=None, read=None, redirect=None)) after connection broken by 'NewConnectionError('<telegram.vendor.ptb_urllib3.urllib3.contrib.socks.SOCKSHTTPSConnection object at 0x1110837b8>: Failed to establish a new connection: 0x02: Connection not allowed by ruleset',)': /bot646613110:AAEaqvqJnNUOqVNNFTmHU5mTEVxN3VJpQlo/deleteWebhook
2018-09-14 19:48:59,953 - WARNING - Retrying (Retry(total=1, connect=None, read=None, redirect=None)) after connection broken by 'NewConnectionError('<telegram.vendor.ptb_urllib3.urllib3.contrib.socks.SOCKSHTTPSConnection object at 0x111083eb8>: Failed to establish a new connection: 0x02: Connection not allowed by ruleset',)': /bot646613110:AAEaqvqJnNUOqVNNFTmHU5mTEVxN3VJpQlo/deleteWebhook
2018-09-14 19:49:00,240 - WARNING - Retrying (Retry(total=0, connect=None, read=None, redirect=None)) after connection broken by 'NewConnectionError('<telegram.vendor.ptb_urllib3.urllib3.contrib.socks.SOCKSHTTPSConnection object at 0x1110a0240>: Failed to establish a new connection: 0x02: Connection not allowed by ruleset',)': /bot646613110:AAEaqvqJnNUOqVNNFTmHU5mTEVxN3VJpQlo/deleteWebhook
2018-09-14 19:49:00,525 - ERROR - Error while bootstrap del webhook: urllib3 HTTPError SOCKSHTTPSConnectionPool(host='api.telegram.org', port=443): Max retries exceeded with url: /bot646613110:AAEaqvqJnNUOqVNNFTmHU5mTEVxN3VJpQlo/deleteWebhook (Caused by NewConnectionError('<telegram.vendor.ptb_urllib3.urllib3.contrib.socks.SOCKSHTTPSConnection object at 0x1110a0390>: Failed to establish a new connection: 0x02: Connection not allowed by ruleset',))
2018-09-14 19:49:00,526 - WARNING - Failed bootstrap phase; try=1 max_retries=-1
2018-09-14 19:49:08,321 - WARNING - Retrying (Retry(total=2, connect=None, read=None, redirect=None)) after connection broken by 'NewConnectionError('<telegram.vendor.ptb_urllib3.urllib3.contrib.socks.SOCKSHTTPSConnection object at 0x1110a0438>: Failed to establish a new connection: 0x02: Connection not allowed by ruleset',)': /bot646613110:AAEaqvqJnNUOqVNNFTmHU5mTEVxN3VJpQlo/deleteWebhook
2018-09-14 19:49:08,607 - WARNING - Retrying (Retry(total=1, connect=None, read=None, redirect=None)) after connection broken by 'NewConnectionError('<telegram.vendor.ptb_urllib3.urllib3.contrib.socks.SOCKSHTTPSConnection object at 0x1110a0908>: Failed to establish a new connection: 0x02: Connection not allowed by ruleset',)': /bot646613110:AAEaqvqJnNUOqVNNFTmHU5mTEVxN3VJpQlo/deleteWebhook
2018-09-14 19:49:08,894 - WARNING - Retrying (Retry(total=0, connect=None, read=None, redirect=None)) after connection broken by 'NewConnectionError('<telegram.vendor.ptb_urllib3.urllib3.contrib.socks.SOCKSHTTPSConnection object at 0x1110a09b0>: Failed to establish a new connection: 0x02: Connection not allowed by ruleset',)': /bot646613110:AAEaqvqJnNUOqVNNFTmHU5mTEVxN3VJpQlo/deleteWebhook
2018-09-14 19:49:09,166 - ERROR - Error while bootstrap del webhook: urllib3 HTTPError SOCKSHTTPSConnectionPool(host='api.telegram.org', port=443): Max retries exceeded with url: /bot646613110:AAEaqvqJnNUOqVNNFTmHU5mTEVxN3VJpQlo/deleteWebhook (Caused by NewConnectionError('<telegram.vendor.ptb_urllib3.urllib3.contrib.socks.SOCKSHTTPSConnection object at 0x1110a0b70>: Failed to establish a new connection: 0x02: Connection not allowed by ruleset',))
2018-09-14 19:49:09,167 - WARNING - Failed bootstrap phase; try=2 max_retries=-1
2018-09-14 19:49:20,721 - WARNING - Retrying (Retry(total=2, connect=None, read=None, redirect=None)) after connection broken by 'NewConnectionError('<telegram.vendor.ptb_urllib3.urllib3.contrib.socks.SOCKSHTTPSConnection object at 0x1110a0630>: Failed to establish a new connection: 0x02: Connection not allowed by ruleset',)': /bot646613110:AAEaqvqJnNUOqVNNFTmHU5mTEVxN3VJpQlo/deleteWebhook
2018-09-14 19:49:21,008 - WARNING - Retrying (Retry(total=1, connect=None, read=None, redirect=None)) after connection broken by 'NewConnectionError('<telegram.vendor.ptb_urllib3.urllib3.contrib.socks.SOCKSHTTPSConnection object at 0x1110a0668>: Failed to establish a new connection: 0x02: Connection not allowed by ruleset',)': /bot646613110:AAEaqvqJnNUOqVNNFTmHU5mTEVxN3VJpQlo/deleteWebhook
2018-09-14 19:49:21,294 - WARNING - Retrying (Retry(total=0, connect=None, read=None, redirect=None)) after connection broken by 'NewConnectionError('<telegram.vendor.ptb_urllib3.urllib3.contrib.socks.SOCKSHTTPSConnection object at 0x1110a05f8>: Failed to establish a new connection: 0x02: Connection not allowed by ruleset',)': /bot646613110:AAEaqvqJnNUOqVNNFTmHU5mTEVxN3VJpQlo/deleteWebhook
2018-09-14 19:49:21,580 - ERROR - Error while bootstrap del webhook: urllib3 HTTPError SOCKSHTTPSConnectionPool(host='api.telegram.org', port=443): Max retries exceeded with url: /bot646613110:AAEaqvqJnNUOqVNNFTmHU5mTEVxN3VJpQlo/deleteWebhook (Caused by NewConnectionError('<telegram.vendor.ptb_urllib3.urllib3.contrib.socks.SOCKSHTTPSConnection object at 0x1110a0400>: Failed to establish a new connection: 0x02: Connection not allowed by ruleset',))
2018-09-14 19:49:21,580 - WARNING - Failed bootstrap phase; try=3 max_retries=-1
2018-09-14 19:49:38,731 - WARNING - Retrying (Retry(total=2, connect=None, read=None, redirect=None)) after connection broken by 'NewConnectionError('<telegram.vendor.ptb_urllib3.urllib3.contrib.socks.SOCKSHTTPSConnection object at 0x1110be048>: Failed to establish a new connection: 0x02: Connection not allowed by ruleset',)': /bot646613110:AAEaqvqJnNUOqVNNFTmHU5mTEVxN3VJpQlo/deleteWebhook
2018-09-14 19:49:39,018 - WARNING - Retrying (Retry(total=1, connect=None, read=None, redirect=None)) after connection broken by 'NewConnectionError('<telegram.vendor.ptb_urllib3.urllib3.contrib.socks.SOCKSHTTPSConnection object at 0x1110be400>: Failed to establish a new connection: 0x02: Connection not allowed by ruleset',)': /bot646613110:AAEaqvqJnNUOqVNNFTmHU5mTEVxN3VJpQlo/deleteWebhook
2018-09-14 19:49:39,302 - WARNING - Retrying (Retry(total=0, connect=None, read=None, redirect=None)) after connection broken by 'NewConnectionError('<telegram.vendor.ptb_urllib3.urllib3.contrib.socks.SOCKSHTTPSConnection object at 0x1110be4a8>: Failed to establish a new connection: 0x02: Connection not allowed by ruleset',)': /bot646613110:AAEaqvqJnNUOqVNNFTmHU5mTEVxN3VJpQlo/deleteWebhook
2018-09-14 19:49:39,601 - ERROR - Error while bootstrap del webhook: urllib3 HTTPError SOCKSHTTPSConnectionPool(host='api.telegram.org', port=443): Max retries exceeded with url: /bot646613110:AAEaqvqJnNUOqVNNFTmHU5mTEVxN3VJpQlo/deleteWebhook (Caused by NewConnectionError('<telegram.vendor.ptb_urllib3.urllib3.contrib.socks.SOCKSHTTPSConnection object at 0x1110be668>: Failed to establish a new connection: 0x02: Connection not allowed by ruleset',))
2018-09-14 19:49:39,602 - WARNING - Failed bootstrap phase; try=4 max_retries=-1
2018-09-14 19:49:56,608 - INFO - Received signal 2 (SIGINT), stopping...
2018-09-15 11:54:24,425 - INFO - Бот запускается
2018-09-15 11:54:25,862 - INFO - User: riokko, Chat id: 67039566, Message: привет
2018-09-15 11:54:26,054 - INFO - Вызван /start
2018-09-15 11:54:26,167 - INFO - Вызван /start
2018-09-15 11:54:26,293 - INFO - Вызван /start
2018-09-15 11:54:26,409 - INFO - Вызван /start
2018-09-15 11:54:39,294 - INFO - Вызван /start
2018-09-15 11:54:59,308 - INFO - Вызван /start
2018-09-15 11:56:14,951 - INFO - User: riokko, Chat id: 67039566, Message: ❤️
2018-09-15 11:57:46,999 - INFO - Received signal 2 (SIGINT), stopping...
2018-09-15 12:10:20,797 - INFO - Бот запускается
2018-09-15 12:10:27,142 - INFO - User: riokko, Chat id: 67039566, Message: привет
2018-09-15 12:11:41,412 - INFO - Received signal 2 (SIGINT), stopping...
2018-09-15 12:11:44,674 - INFO - Бот запускается
2018-09-15 12:14:28,530 - INFO - Received signal 2 (SIGINT), stopping...
2018-09-15 12:14:30,950 - INFO - Бот запускается
2018-09-15 12:15:47,894 - INFO - Received signal 2 (SIGINT), stopping...
2018-09-15 12:15:51,286 - INFO - Бот запускается
2018-09-15 12:16:06,492 - INFO - Received signal 2 (SIGINT), stopping...
2018-09-15 12:50:12,327 - INFO - Бот запускается
2018-09-15 12:58:09,472 - INFO - Received signal 2 (SIGINT), stopping...
2018-09-15 13:02:08,507 - INFO - Бот запускается
2018-09-15 13:02:20,784 - ERROR - An uncaught error was raised while processing the update
Traceback (most recent call last):
  File "/Library/Frameworks/Python.framework/Versions/3.6/lib/python3.6/site-packages/telegram/ext/dispatcher.py", line 279, in process_update
    handler.handle_update(update, self)
  File "/Library/Frameworks/Python.framework/Versions/3.6/lib/python3.6/site-packages/telegram/ext/commandhandler.py", line 173, in handle_update
    return self.callback(dispatcher.bot, update, **optional_args)
  File "bot_ephem.py", line 28, in planet_ephem
    today = datetime.strftime('%Y/%m/%d')
TypeError: descriptor 'strftime' requires a 'datetime.date' object but received a 'str'
2018-09-15 13:04:12,993 - INFO - Received signal 2 (SIGINT), stopping...
2018-09-15 13:04:18,496 - INFO - Бот запускается
2018-09-15 13:04:31,268 - ERROR - An uncaught error was raised while processing the update
Traceback (most recent call last):
  File "/Library/Frameworks/Python.framework/Versions/3.6/lib/python3.6/site-packages/telegram/ext/dispatcher.py", line 279, in process_update
    handler.handle_update(update, self)
  File "/Library/Frameworks/Python.framework/Versions/3.6/lib/python3.6/site-packages/telegram/ext/commandhandler.py", line 173, in handle_update
    return self.callback(dispatcher.bot, update, **optional_args)
  File "bot_ephem.py", line 28, in planet_ephem
    today = datetime.date.strftime('%Y/%m/%d')
AttributeError: 'method_descriptor' object has no attribute 'strftime'
2018-09-15 13:05:21,037 - INFO - Received signal 2 (SIGINT), stopping...
2018-09-15 13:06:32,867 - INFO - Бот запускается
2018-09-15 13:06:40,043 - WARNING - A TelegramError was raised while processing the Update
2018-09-15 13:06:40,043 - ERROR - No error handlers are registered, logging exception.
Traceback (most recent call last):
  File "/Library/Frameworks/Python.framework/Versions/3.6/lib/python3.6/site-packages/telegram/ext/dispatcher.py", line 279, in process_update
    handler.handle_update(update, self)
  File "/Library/Frameworks/Python.framework/Versions/3.6/lib/python3.6/site-packages/telegram/ext/commandhandler.py", line 173, in handle_update
    return self.callback(dispatcher.bot, update, **optional_args)
  File "bot_ephem.py", line 30, in planet_ephem
    update.message.reply_text(user_planet, today)
  File "/Library/Frameworks/Python.framework/Versions/3.6/lib/python3.6/site-packages/telegram/message.py", line 455, in reply_text
    return self.bot.send_message(self.chat_id, *args, **kwargs)
  File "/Library/Frameworks/Python.framework/Versions/3.6/lib/python3.6/site-packages/telegram/bot.py", line 65, in decorator
    result = func(self, *args, **kwargs)
  File "/Library/Frameworks/Python.framework/Versions/3.6/lib/python3.6/site-packages/telegram/bot.py", line 90, in decorator
    result = self._request.post(url, data, timeout=kwargs.get('timeout'))
  File "/Library/Frameworks/Python.framework/Versions/3.6/lib/python3.6/site-packages/telegram/utils/request.py", line 309, in post
    headers={'Content-Type': 'application/json'})
  File "/Library/Frameworks/Python.framework/Versions/3.6/lib/python3.6/site-packages/telegram/utils/request.py", line 223, in _request_wrapper
    raise BadRequest(message)
telegram.error.BadRequest: Unsupported parse_mode
2018-09-15 13:06:56,788 - INFO - Received signal 2 (SIGINT), stopping...
2018-09-15 13:07:03,223 - INFO - Бот запускается
2018-09-15 13:11:22,749 - INFO - Вызван /start
2018-09-15 13:11:28,799 - ERROR - An uncaught error was raised while processing the update
Traceback (most recent call last):
  File "/Library/Frameworks/Python.framework/Versions/3.6/lib/python3.6/site-packages/telegram/ext/dispatcher.py", line 279, in process_update
    handler.handle_update(update, self)
  File "/Library/Frameworks/Python.framework/Versions/3.6/lib/python3.6/site-packages/telegram/ext/commandhandler.py", line 173, in handle_update
    return self.callback(dispatcher.bot, update, **optional_args)
  File "bot_ephem.py", line 27, in planet_ephem
    user_planet = user_planet.split(" ")[1].capitalize()
IndexError: list index out of range
2018-09-15 13:12:59,244 - INFO - Received signal 2 (SIGINT), stopping...
2018-09-15 13:13:04,617 - INFO - Бот запускается
2018-09-15 13:16:47,368 - INFO - Received signal 2 (SIGINT), stopping...
2018-09-15 13:16:52,468 - INFO - Бот запускается
2018-09-15 13:17:01,742 - ERROR - An uncaught error was raised while processing the update
Traceback (most recent call last):
  File "/Library/Frameworks/Python.framework/Versions/3.6/lib/python3.6/site-packages/telegram/ext/dispatcher.py", line 279, in process_update
    handler.handle_update(update, self)
  File "/Library/Frameworks/Python.framework/Versions/3.6/lib/python3.6/site-packages/telegram/ext/commandhandler.py", line 173, in handle_update
    return self.callback(dispatcher.bot, update, **optional_args)
  File "bot_ephem.py", line 30, in planet_ephem
    user_planet = ephem.user_planet(today)
AttributeError: module 'ephem' has no attribute 'user_planet'
2018-09-15 13:22:53,962 - INFO - Received signal 2 (SIGINT), stopping...
2018-09-15 13:22:59,166 - INFO - Бот запускается
2018-09-15 13:30:43,683 - WARNING - Retrying (Retry(total=2, connect=None, read=None, redirect=None)) after connection broken by 'NewConnectionError('<telegram.vendor.ptb_urllib3.urllib3.contrib.socks.SOCKSHTTPSConnection object at 0x111faf0f0>: Failed to establish a new connection: [Errno 8] nodename nor servname provided, or not known',)': /bot646613110:AAEaqvqJnNUOqVNNFTmHU5mTEVxN3VJpQlo/getUpdates
2018-09-15 13:30:43,687 - WARNING - Retrying (Retry(total=1, connect=None, read=None, redirect=None)) after connection broken by 'NewConnectionError('<telegram.vendor.ptb_urllib3.urllib3.contrib.socks.SOCKSHTTPSConnection object at 0x111faf2b0>: Failed to establish a new connection: [Errno 8] nodename nor servname provided, or not known',)': /bot646613110:AAEaqvqJnNUOqVNNFTmHU5mTEVxN3VJpQlo/getUpdates
2018-09-15 13:30:43,713 - WARNING - Retrying (Retry(total=0, connect=None, read=None, redirect=None)) after connection broken by 'NewConnectionError('<telegram.vendor.ptb_urllib3.urllib3.contrib.socks.SOCKSHTTPSConnection object at 0x111faf390>: Failed to establish a new connection: [Errno 8] nodename nor servname provided, or not known',)': /bot646613110:AAEaqvqJnNUOqVNNFTmHU5mTEVxN3VJpQlo/getUpdates
2018-09-15 13:30:43,717 - ERROR - Error while getting Updates: urllib3 HTTPError SOCKSHTTPSConnectionPool(host='api.telegram.org', port=443): Max retries exceeded with url: /bot646613110:AAEaqvqJnNUOqVNNFTmHU5mTEVxN3VJpQlo/getUpdates (Caused by NewConnectionError('<telegram.vendor.ptb_urllib3.urllib3.contrib.socks.SOCKSHTTPSConnection object at 0x111fa3f28>: Failed to establish a new connection: [Errno 8] nodename nor servname provided, or not known',))
2018-09-15 13:30:43,718 - ERROR - No error handlers are registered, logging exception.
Traceback (most recent call last):
  File "/Library/Frameworks/Python.framework/Versions/3.6/lib/python3.6/site-packages/telegram/vendor/ptb_urllib3/urllib3/contrib/socks.py", line 88, in _new_conn
    **extra_kw
  File "/Library/Frameworks/Python.framework/Versions/3.6/lib/python3.6/site-packages/socks.py", line 233, in create_connection
    for r in socket.getaddrinfo(proxy_addr, proxy_port, 0, socket.SOCK_STREAM):
  File "/Library/Frameworks/Python.framework/Versions/3.6/lib/python3.6/socket.py", line 745, in getaddrinfo
    for res in _socket.getaddrinfo(host, port, family, type, proto, flags):
socket.gaierror: [Errno 8] nodename nor servname provided, or not known

During handling of the above exception, another exception occurred:

Traceback (most recent call last):
  File "/Library/Frameworks/Python.framework/Versions/3.6/lib/python3.6/site-packages/telegram/vendor/ptb_urllib3/urllib3/connectionpool.py", line 617, in urlopen
    chunked=chunked)
  File "/Library/Frameworks/Python.framework/Versions/3.6/lib/python3.6/site-packages/telegram/vendor/ptb_urllib3/urllib3/connectionpool.py", line 360, in _make_request
    self._validate_conn(conn)
  File "/Library/Frameworks/Python.framework/Versions/3.6/lib/python3.6/site-packages/telegram/vendor/ptb_urllib3/urllib3/connectionpool.py", line 857, in _validate_conn
    super(HTTPSConnectionPool, self)._validate_conn(conn)
  File "/Library/Frameworks/Python.framework/Versions/3.6/lib/python3.6/site-packages/telegram/vendor/ptb_urllib3/urllib3/connectionpool.py", line 289, in _validate_conn
    conn.connect()
  File "/Library/Frameworks/Python.framework/Versions/3.6/lib/python3.6/site-packages/telegram/vendor/ptb_urllib3/urllib3/connection.py", line 284, in connect
    conn = self._new_conn()
  File "/Library/Frameworks/Python.framework/Versions/3.6/lib/python3.6/site-packages/telegram/vendor/ptb_urllib3/urllib3/contrib/socks.py", line 120, in _new_conn
    self, "Failed to establish a new connection: %s" % e)
telegram.vendor.ptb_urllib3.urllib3.exceptions.NewConnectionError: <telegram.vendor.ptb_urllib3.urllib3.contrib.socks.SOCKSHTTPSConnection object at 0x111fa3f28>: Failed to establish a new connection: [Errno 8] nodename nor servname provided, or not known

During handling of the above exception, another exception occurred:

Traceback (most recent call last):
  File "/Library/Frameworks/Python.framework/Versions/3.6/lib/python3.6/site-packages/telegram/utils/request.py", line 203, in _request_wrapper
    resp = self._con_pool.request(*args, **kwargs)
  File "/Library/Frameworks/Python.framework/Versions/3.6/lib/python3.6/site-packages/telegram/vendor/ptb_urllib3/urllib3/request.py", line 70, in request
    **urlopen_kw)
  File "/Library/Frameworks/Python.framework/Versions/3.6/lib/python3.6/site-packages/telegram/vendor/ptb_urllib3/urllib3/request.py", line 148, in request_encode_body
    return self.urlopen(method, url, **extra_kw)
  File "/Library/Frameworks/Python.framework/Versions/3.6/lib/python3.6/site-packages/telegram/vendor/ptb_urllib3/urllib3/poolmanager.py", line 244, in urlopen
    response = conn.urlopen(method, u.request_uri, **kw)
  File "/Library/Frameworks/Python.framework/Versions/3.6/lib/python3.6/site-packages/telegram/vendor/ptb_urllib3/urllib3/connectionpool.py", line 695, in urlopen
    **response_kw)
  File "/Library/Frameworks/Python.framework/Versions/3.6/lib/python3.6/site-packages/telegram/vendor/ptb_urllib3/urllib3/connectionpool.py", line 695, in urlopen
    **response_kw)
  File "/Library/Frameworks/Python.framework/Versions/3.6/lib/python3.6/site-packages/telegram/vendor/ptb_urllib3/urllib3/connectionpool.py", line 695, in urlopen
    **response_kw)
  File "/Library/Frameworks/Python.framework/Versions/3.6/lib/python3.6/site-packages/telegram/vendor/ptb_urllib3/urllib3/connectionpool.py", line 666, in urlopen
    _stacktrace=sys.exc_info()[2])
  File "/Library/Frameworks/Python.framework/Versions/3.6/lib/python3.6/site-packages/telegram/vendor/ptb_urllib3/urllib3/util/retry.py", line 376, in increment
    raise MaxRetryError(_pool, url, error or ResponseError(cause))
telegram.vendor.ptb_urllib3.urllib3.exceptions.MaxRetryError: SOCKSHTTPSConnectionPool(host='api.telegram.org', port=443): Max retries exceeded with url: /bot646613110:AAEaqvqJnNUOqVNNFTmHU5mTEVxN3VJpQlo/getUpdates (Caused by NewConnectionError('<telegram.vendor.ptb_urllib3.urllib3.contrib.socks.SOCKSHTTPSConnection object at 0x111fa3f28>: Failed to establish a new connection: [Errno 8] nodename nor servname provided, or not known',))

During handling of the above exception, another exception occurred:

Traceback (most recent call last):
  File "/Library/Frameworks/Python.framework/Versions/3.6/lib/python3.6/site-packages/telegram/ext/updater.py", line 319, in _network_loop_retry
    if not action_cb():
  File "/Library/Frameworks/Python.framework/Versions/3.6/lib/python3.6/site-packages/telegram/ext/updater.py", line 280, in polling_action_cb
    allowed_updates=allowed_updates)
  File "/Library/Frameworks/Python.framework/Versions/3.6/lib/python3.6/site-packages/telegram/bot.py", line 65, in decorator
    result = func(self, *args, **kwargs)
  File "/Library/Frameworks/Python.framework/Versions/3.6/lib/python3.6/site-packages/telegram/bot.py", line 1975, in get_updates
    result = self._request.post(url, data, timeout=float(read_latency) + float(timeout))
  File "/Library/Frameworks/Python.framework/Versions/3.6/lib/python3.6/site-packages/telegram/utils/request.py", line 309, in post
    headers={'Content-Type': 'application/json'})
  File "/Library/Frameworks/Python.framework/Versions/3.6/lib/python3.6/site-packages/telegram/utils/request.py", line 209, in _request_wrapper
    raise NetworkError('urllib3 HTTPError {0}'.format(error))
telegram.error.NetworkError: urllib3 HTTPError SOCKSHTTPSConnectionPool(host='api.telegram.org', port=443): Max retries exceeded with url: /bot646613110:AAEaqvqJnNUOqVNNFTmHU5mTEVxN3VJpQlo/getUpdates (Caused by NewConnectionError('<telegram.vendor.ptb_urllib3.urllib3.contrib.socks.SOCKSHTTPSConnection object at 0x111fa3f28>: Failed to establish a new connection: [Errno 8] nodename nor servname provided, or not known',))
2018-09-15 13:30:44,722 - WARNING - Retrying (Retry(total=2, connect=None, read=None, redirect=None)) after connection broken by 'NewConnectionError('<telegram.vendor.ptb_urllib3.urllib3.contrib.socks.SOCKSHTTPSConnection object at 0x111fa3710>: Failed to establish a new connection: [Errno 8] nodename nor servname provided, or not known',)': /bot646613110:AAEaqvqJnNUOqVNNFTmHU5mTEVxN3VJpQlo/getUpdates
2018-09-15 13:30:44,724 - WARNING - Retrying (Retry(total=1, connect=None, read=None, redirect=None)) after connection broken by 'NewConnectionError('<telegram.vendor.ptb_urllib3.urllib3.contrib.socks.SOCKSHTTPSConnection object at 0x111e637b8>: Failed to establish a new connection: [Errno 8] nodename nor servname provided, or not known',)': /bot646613110:AAEaqvqJnNUOqVNNFTmHU5mTEVxN3VJpQlo/getUpdates
2018-09-15 13:30:44,726 - WARNING - Retrying (Retry(total=0, connect=None, read=None, redirect=None)) after connection broken by 'NewConnectionError('<telegram.vendor.ptb_urllib3.urllib3.contrib.socks.SOCKSHTTPSConnection object at 0x111e63ac8>: Failed to establish a new connection: [Errno 8] nodename nor servname provided, or not known',)': /bot646613110:AAEaqvqJnNUOqVNNFTmHU5mTEVxN3VJpQlo/getUpdates
2018-09-15 13:30:44,727 - ERROR - Error while getting Updates: urllib3 HTTPError SOCKSHTTPSConnectionPool(host='api.telegram.org', port=443): Max retries exceeded with url: /bot646613110:AAEaqvqJnNUOqVNNFTmHU5mTEVxN3VJpQlo/getUpdates (Caused by NewConnectionError('<telegram.vendor.ptb_urllib3.urllib3.contrib.socks.SOCKSHTTPSConnection object at 0x111e63fd0>: Failed to establish a new connection: [Errno 8] nodename nor servname provided, or not known',))
2018-09-15 13:30:44,727 - ERROR - No error handlers are registered, logging exception.
Traceback (most recent call last):
  File "/Library/Frameworks/Python.framework/Versions/3.6/lib/python3.6/site-packages/telegram/vendor/ptb_urllib3/urllib3/contrib/socks.py", line 88, in _new_conn
    **extra_kw
  File "/Library/Frameworks/Python.framework/Versions/3.6/lib/python3.6/site-packages/socks.py", line 233, in create_connection
    for r in socket.getaddrinfo(proxy_addr, proxy_port, 0, socket.SOCK_STREAM):
  File "/Library/Frameworks/Python.framework/Versions/3.6/lib/python3.6/socket.py", line 745, in getaddrinfo
    for res in _socket.getaddrinfo(host, port, family, type, proto, flags):
socket.gaierror: [Errno 8] nodename nor servname provided, or not known

During handling of the above exception, another exception occurred:

Traceback (most recent call last):
  File "/Library/Frameworks/Python.framework/Versions/3.6/lib/python3.6/site-packages/telegram/vendor/ptb_urllib3/urllib3/connectionpool.py", line 617, in urlopen
    chunked=chunked)
  File "/Library/Frameworks/Python.framework/Versions/3.6/lib/python3.6/site-packages/telegram/vendor/ptb_urllib3/urllib3/connectionpool.py", line 360, in _make_request
    self._validate_conn(conn)
  File "/Library/Frameworks/Python.framework/Versions/3.6/lib/python3.6/site-packages/telegram/vendor/ptb_urllib3/urllib3/connectionpool.py", line 857, in _validate_conn
    super(HTTPSConnectionPool, self)._validate_conn(conn)
  File "/Library/Frameworks/Python.framework/Versions/3.6/lib/python3.6/site-packages/telegram/vendor/ptb_urllib3/urllib3/connectionpool.py", line 289, in _validate_conn
    conn.connect()
  File "/Library/Frameworks/Python.framework/Versions/3.6/lib/python3.6/site-packages/telegram/vendor/ptb_urllib3/urllib3/connection.py", line 284, in connect
    conn = self._new_conn()
  File "/Library/Frameworks/Python.framework/Versions/3.6/lib/python3.6/site-packages/telegram/vendor/ptb_urllib3/urllib3/contrib/socks.py", line 120, in _new_conn
    self, "Failed to establish a new connection: %s" % e)
telegram.vendor.ptb_urllib3.urllib3.exceptions.NewConnectionError: <telegram.vendor.ptb_urllib3.urllib3.contrib.socks.SOCKSHTTPSConnection object at 0x111e63fd0>: Failed to establish a new connection: [Errno 8] nodename nor servname provided, or not known

During handling of the above exception, another exception occurred:

Traceback (most recent call last):
  File "/Library/Frameworks/Python.framework/Versions/3.6/lib/python3.6/site-packages/telegram/utils/request.py", line 203, in _request_wrapper
    resp = self._con_pool.request(*args, **kwargs)
  File "/Library/Frameworks/Python.framework/Versions/3.6/lib/python3.6/site-packages/telegram/vendor/ptb_urllib3/urllib3/request.py", line 70, in request
    **urlopen_kw)
  File "/Library/Frameworks/Python.framework/Versions/3.6/lib/python3.6/site-packages/telegram/vendor/ptb_urllib3/urllib3/request.py", line 148, in request_encode_body
    return self.urlopen(method, url, **extra_kw)
  File "/Library/Frameworks/Python.framework/Versions/3.6/lib/python3.6/site-packages/telegram/vendor/ptb_urllib3/urllib3/poolmanager.py", line 244, in urlopen
    response = conn.urlopen(method, u.request_uri, **kw)
  File "/Library/Frameworks/Python.framework/Versions/3.6/lib/python3.6/site-packages/telegram/vendor/ptb_urllib3/urllib3/connectionpool.py", line 695, in urlopen
    **response_kw)
  File "/Library/Frameworks/Python.framework/Versions/3.6/lib/python3.6/site-packages/telegram/vendor/ptb_urllib3/urllib3/connectionpool.py", line 695, in urlopen
    **response_kw)
  File "/Library/Frameworks/Python.framework/Versions/3.6/lib/python3.6/site-packages/telegram/vendor/ptb_urllib3/urllib3/connectionpool.py", line 695, in urlopen
    **response_kw)
  File "/Library/Frameworks/Python.framework/Versions/3.6/lib/python3.6/site-packages/telegram/vendor/ptb_urllib3/urllib3/connectionpool.py", line 666, in urlopen
    _stacktrace=sys.exc_info()[2])
  File "/Library/Frameworks/Python.framework/Versions/3.6/lib/python3.6/site-packages/telegram/vendor/ptb_urllib3/urllib3/util/retry.py", line 376, in increment
    raise MaxRetryError(_pool, url, error or ResponseError(cause))
telegram.vendor.ptb_urllib3.urllib3.exceptions.MaxRetryError: SOCKSHTTPSConnectionPool(host='api.telegram.org', port=443): Max retries exceeded with url: /bot646613110:AAEaqvqJnNUOqVNNFTmHU5mTEVxN3VJpQlo/getUpdates (Caused by NewConnectionError('<telegram.vendor.ptb_urllib3.urllib3.contrib.socks.SOCKSHTTPSConnection object at 0x111e63fd0>: Failed to establish a new connection: [Errno 8] nodename nor servname provided, or not known',))

During handling of the above exception, another exception occurred:

Traceback (most recent call last):
  File "/Library/Frameworks/Python.framework/Versions/3.6/lib/python3.6/site-packages/telegram/ext/updater.py", line 319, in _network_loop_retry
    if not action_cb():
  File "/Library/Frameworks/Python.framework/Versions/3.6/lib/python3.6/site-packages/telegram/ext/updater.py", line 280, in polling_action_cb
    allowed_updates=allowed_updates)
  File "/Library/Frameworks/Python.framework/Versions/3.6/lib/python3.6/site-packages/telegram/bot.py", line 65, in decorator
    result = func(self, *args, **kwargs)
  File "/Library/Frameworks/Python.framework/Versions/3.6/lib/python3.6/site-packages/telegram/bot.py", line 1975, in get_updates
    result = self._request.post(url, data, timeout=float(read_latency) + float(timeout))
  File "/Library/Frameworks/Python.framework/Versions/3.6/lib/python3.6/site-packages/telegram/utils/request.py", line 309, in post
    headers={'Content-Type': 'application/json'})
  File "/Library/Frameworks/Python.framework/Versions/3.6/lib/python3.6/site-packages/telegram/utils/request.py", line 209, in _request_wrapper
    raise NetworkError('urllib3 HTTPError {0}'.format(error))
telegram.error.NetworkError: urllib3 HTTPError SOCKSHTTPSConnectionPool(host='api.telegram.org', port=443): Max retries exceeded with url: /bot646613110:AAEaqvqJnNUOqVNNFTmHU5mTEVxN3VJpQlo/getUpdates (Caused by NewConnectionError('<telegram.vendor.ptb_urllib3.urllib3.contrib.socks.SOCKSHTTPSConnection object at 0x111e63fd0>: Failed to establish a new connection: [Errno 8] nodename nor servname provided, or not known',))
2018-09-15 13:30:46,233 - WARNING - Retrying (Retry(total=2, connect=None, read=None, redirect=None)) after connection broken by 'NewConnectionError('<telegram.vendor.ptb_urllib3.urllib3.contrib.socks.SOCKSHTTPSConnection object at 0x111e63e10>: Failed to establish a new connection: [Errno 8] nodename nor servname provided, or not known',)': /bot646613110:AAEaqvqJnNUOqVNNFTmHU5mTEVxN3VJpQlo/getUpdates
2018-09-15 13:30:46,234 - WARNING - Retrying (Retry(total=1, connect=None, read=None, redirect=None)) after connection broken by 'NewConnectionError('<telegram.vendor.ptb_urllib3.urllib3.contrib.socks.SOCKSHTTPSConnection object at 0x111e63dd8>: Failed to establish a new connection: [Errno 8] nodename nor servname provided, or not known',)': /bot646613110:AAEaqvqJnNUOqVNNFTmHU5mTEVxN3VJpQlo/getUpdates
2018-09-15 13:30:46,235 - WARNING - Retrying (Retry(total=0, connect=None, read=None, redirect=None)) after connection broken by 'NewConnectionError('<telegram.vendor.ptb_urllib3.urllib3.contrib.socks.SOCKSHTTPSConnection object at 0x111e63898>: Failed to establish a new connection: [Errno 8] nodename nor servname provided, or not known',)': /bot646613110:AAEaqvqJnNUOqVNNFTmHU5mTEVxN3VJpQlo/getUpdates
2018-09-15 13:30:46,236 - ERROR - Error while getting Updates: urllib3 HTTPError SOCKSHTTPSConnectionPool(host='api.telegram.org', port=443): Max retries exceeded with url: /bot646613110:AAEaqvqJnNUOqVNNFTmHU5mTEVxN3VJpQlo/getUpdates (Caused by NewConnectionError('<telegram.vendor.ptb_urllib3.urllib3.contrib.socks.SOCKSHTTPSConnection object at 0x111e63358>: Failed to establish a new connection: [Errno 8] nodename nor servname provided, or not known',))
2018-09-15 13:30:46,236 - ERROR - No error handlers are registered, logging exception.
Traceback (most recent call last):
  File "/Library/Frameworks/Python.framework/Versions/3.6/lib/python3.6/site-packages/telegram/vendor/ptb_urllib3/urllib3/contrib/socks.py", line 88, in _new_conn
    **extra_kw
  File "/Library/Frameworks/Python.framework/Versions/3.6/lib/python3.6/site-packages/socks.py", line 233, in create_connection
    for r in socket.getaddrinfo(proxy_addr, proxy_port, 0, socket.SOCK_STREAM):
  File "/Library/Frameworks/Python.framework/Versions/3.6/lib/python3.6/socket.py", line 745, in getaddrinfo
    for res in _socket.getaddrinfo(host, port, family, type, proto, flags):
socket.gaierror: [Errno 8] nodename nor servname provided, or not known

During handling of the above exception, another exception occurred:

Traceback (most recent call last):
  File "/Library/Frameworks/Python.framework/Versions/3.6/lib/python3.6/site-packages/telegram/vendor/ptb_urllib3/urllib3/connectionpool.py", line 617, in urlopen
    chunked=chunked)
  File "/Library/Frameworks/Python.framework/Versions/3.6/lib/python3.6/site-packages/telegram/vendor/ptb_urllib3/urllib3/connectionpool.py", line 360, in _make_request
    self._validate_conn(conn)
  File "/Library/Frameworks/Python.framework/Versions/3.6/lib/python3.6/site-packages/telegram/vendor/ptb_urllib3/urllib3/connectionpool.py", line 857, in _validate_conn
    super(HTTPSConnectionPool, self)._validate_conn(conn)
  File "/Library/Frameworks/Python.framework/Versions/3.6/lib/python3.6/site-packages/telegram/vendor/ptb_urllib3/urllib3/connectionpool.py", line 289, in _validate_conn
    conn.connect()
  File "/Library/Frameworks/Python.framework/Versions/3.6/lib/python3.6/site-packages/telegram/vendor/ptb_urllib3/urllib3/connection.py", line 284, in connect
    conn = self._new_conn()
  File "/Library/Frameworks/Python.framework/Versions/3.6/lib/python3.6/site-packages/telegram/vendor/ptb_urllib3/urllib3/contrib/socks.py", line 120, in _new_conn
    self, "Failed to establish a new connection: %s" % e)
telegram.vendor.ptb_urllib3.urllib3.exceptions.NewConnectionError: <telegram.vendor.ptb_urllib3.urllib3.contrib.socks.SOCKSHTTPSConnection object at 0x111e63358>: Failed to establish a new connection: [Errno 8] nodename nor servname provided, or not known

During handling of the above exception, another exception occurred:

Traceback (most recent call last):
  File "/Library/Frameworks/Python.framework/Versions/3.6/lib/python3.6/site-packages/telegram/utils/request.py", line 203, in _request_wrapper
    resp = self._con_pool.request(*args, **kwargs)
  File "/Library/Frameworks/Python.framework/Versions/3.6/lib/python3.6/site-packages/telegram/vendor/ptb_urllib3/urllib3/request.py", line 70, in request
    **urlopen_kw)
  File "/Library/Frameworks/Python.framework/Versions/3.6/lib/python3.6/site-packages/telegram/vendor/ptb_urllib3/urllib3/request.py", line 148, in request_encode_body
    return self.urlopen(method, url, **extra_kw)
  File "/Library/Frameworks/Python.framework/Versions/3.6/lib/python3.6/site-packages/telegram/vendor/ptb_urllib3/urllib3/poolmanager.py", line 244, in urlopen
    response = conn.urlopen(method, u.request_uri, **kw)
  File "/Library/Frameworks/Python.framework/Versions/3.6/lib/python3.6/site-packages/telegram/vendor/ptb_urllib3/urllib3/connectionpool.py", line 695, in urlopen
    **response_kw)
  File "/Library/Frameworks/Python.framework/Versions/3.6/lib/python3.6/site-packages/telegram/vendor/ptb_urllib3/urllib3/connectionpool.py", line 695, in urlopen
    **response_kw)
  File "/Library/Frameworks/Python.framework/Versions/3.6/lib/python3.6/site-packages/telegram/vendor/ptb_urllib3/urllib3/connectionpool.py", line 695, in urlopen
    **response_kw)
  File "/Library/Frameworks/Python.framework/Versions/3.6/lib/python3.6/site-packages/telegram/vendor/ptb_urllib3/urllib3/connectionpool.py", line 666, in urlopen
    _stacktrace=sys.exc_info()[2])
  File "/Library/Frameworks/Python.framework/Versions/3.6/lib/python3.6/site-packages/telegram/vendor/ptb_urllib3/urllib3/util/retry.py", line 376, in increment
    raise MaxRetryError(_pool, url, error or ResponseError(cause))
telegram.vendor.ptb_urllib3.urllib3.exceptions.MaxRetryError: SOCKSHTTPSConnectionPool(host='api.telegram.org', port=443): Max retries exceeded with url: /bot646613110:AAEaqvqJnNUOqVNNFTmHU5mTEVxN3VJpQlo/getUpdates (Caused by NewConnectionError('<telegram.vendor.ptb_urllib3.urllib3.contrib.socks.SOCKSHTTPSConnection object at 0x111e63358>: Failed to establish a new connection: [Errno 8] nodename nor servname provided, or not known',))

During handling of the above exception, another exception occurred:

Traceback (most recent call last):
  File "/Library/Frameworks/Python.framework/Versions/3.6/lib/python3.6/site-packages/telegram/ext/updater.py", line 319, in _network_loop_retry
    if not action_cb():
  File "/Library/Frameworks/Python.framework/Versions/3.6/lib/python3.6/site-packages/telegram/ext/updater.py", line 280, in polling_action_cb
    allowed_updates=allowed_updates)
  File "/Library/Frameworks/Python.framework/Versions/3.6/lib/python3.6/site-packages/telegram/bot.py", line 65, in decorator
    result = func(self, *args, **kwargs)
  File "/Library/Frameworks/Python.framework/Versions/3.6/lib/python3.6/site-packages/telegram/bot.py", line 1975, in get_updates
    result = self._request.post(url, data, timeout=float(read_latency) + float(timeout))
  File "/Library/Frameworks/Python.framework/Versions/3.6/lib/python3.6/site-packages/telegram/utils/request.py", line 309, in post
    headers={'Content-Type': 'application/json'})
  File "/Library/Frameworks/Python.framework/Versions/3.6/lib/python3.6/site-packages/telegram/utils/request.py", line 209, in _request_wrapper
    raise NetworkError('urllib3 HTTPError {0}'.format(error))
telegram.error.NetworkError: urllib3 HTTPError SOCKSHTTPSConnectionPool(host='api.telegram.org', port=443): Max retries exceeded with url: /bot646613110:AAEaqvqJnNUOqVNNFTmHU5mTEVxN3VJpQlo/getUpdates (Caused by NewConnectionError('<telegram.vendor.ptb_urllib3.urllib3.contrib.socks.SOCKSHTTPSConnection object at 0x111e63358>: Failed to establish a new connection: [Errno 8] nodename nor servname provided, or not known',))
2018-09-15 13:30:48,498 - WARNING - Retrying (Retry(total=2, connect=None, read=None, redirect=None)) after connection broken by 'NewConnectionError('<telegram.vendor.ptb_urllib3.urllib3.contrib.socks.SOCKSHTTPSConnection object at 0x111e63e48>: Failed to establish a new connection: [Errno 8] nodename nor servname provided, or not known',)': /bot646613110:AAEaqvqJnNUOqVNNFTmHU5mTEVxN3VJpQlo/getUpdates
2018-09-15 13:30:48,499 - WARNING - Retrying (Retry(total=1, connect=None, read=None, redirect=None)) after connection broken by 'NewConnectionError('<telegram.vendor.ptb_urllib3.urllib3.contrib.socks.SOCKSHTTPSConnection object at 0x111e63588>: Failed to establish a new connection: [Errno 8] nodename nor servname provided, or not known',)': /bot646613110:AAEaqvqJnNUOqVNNFTmHU5mTEVxN3VJpQlo/getUpdates
2018-09-15 13:30:48,500 - WARNING - Retrying (Retry(total=0, connect=None, read=None, redirect=None)) after connection broken by 'NewConnectionError('<telegram.vendor.ptb_urllib3.urllib3.contrib.socks.SOCKSHTTPSConnection object at 0x111faf470>: Failed to establish a new connection: [Errno 8] nodename nor servname provided, or not known',)': /bot646613110:AAEaqvqJnNUOqVNNFTmHU5mTEVxN3VJpQlo/getUpdates
2018-09-15 13:30:48,501 - ERROR - Error while getting Updates: urllib3 HTTPError SOCKSHTTPSConnectionPool(host='api.telegram.org', port=443): Max retries exceeded with url: /bot646613110:AAEaqvqJnNUOqVNNFTmHU5mTEVxN3VJpQlo/getUpdates (Caused by NewConnectionError('<telegram.vendor.ptb_urllib3.urllib3.contrib.socks.SOCKSHTTPSConnection object at 0x111faf550>: Failed to establish a new connection: [Errno 8] nodename nor servname provided, or not known',))
2018-09-15 13:30:48,501 - ERROR - No error handlers are registered, logging exception.
Traceback (most recent call last):
  File "/Library/Frameworks/Python.framework/Versions/3.6/lib/python3.6/site-packages/telegram/vendor/ptb_urllib3/urllib3/contrib/socks.py", line 88, in _new_conn
    **extra_kw
  File "/Library/Frameworks/Python.framework/Versions/3.6/lib/python3.6/site-packages/socks.py", line 233, in create_connection
    for r in socket.getaddrinfo(proxy_addr, proxy_port, 0, socket.SOCK_STREAM):
  File "/Library/Frameworks/Python.framework/Versions/3.6/lib/python3.6/socket.py", line 745, in getaddrinfo
    for res in _socket.getaddrinfo(host, port, family, type, proto, flags):
socket.gaierror: [Errno 8] nodename nor servname provided, or not known

During handling of the above exception, another exception occurred:

Traceback (most recent call last):
  File "/Library/Frameworks/Python.framework/Versions/3.6/lib/python3.6/site-packages/telegram/vendor/ptb_urllib3/urllib3/connectionpool.py", line 617, in urlopen
    chunked=chunked)
  File "/Library/Frameworks/Python.framework/Versions/3.6/lib/python3.6/site-packages/telegram/vendor/ptb_urllib3/urllib3/connectionpool.py", line 360, in _make_request
    self._validate_conn(conn)
  File "/Library/Frameworks/Python.framework/Versions/3.6/lib/python3.6/site-packages/telegram/vendor/ptb_urllib3/urllib3/connectionpool.py", line 857, in _validate_conn
    super(HTTPSConnectionPool, self)._validate_conn(conn)
  File "/Library/Frameworks/Python.framework/Versions/3.6/lib/python3.6/site-packages/telegram/vendor/ptb_urllib3/urllib3/connectionpool.py", line 289, in _validate_conn
    conn.connect()
  File "/Library/Frameworks/Python.framework/Versions/3.6/lib/python3.6/site-packages/telegram/vendor/ptb_urllib3/urllib3/connection.py", line 284, in connect
    conn = self._new_conn()
  File "/Library/Frameworks/Python.framework/Versions/3.6/lib/python3.6/site-packages/telegram/vendor/ptb_urllib3/urllib3/contrib/socks.py", line 120, in _new_conn
    self, "Failed to establish a new connection: %s" % e)
telegram.vendor.ptb_urllib3.urllib3.exceptions.NewConnectionError: <telegram.vendor.ptb_urllib3.urllib3.contrib.socks.SOCKSHTTPSConnection object at 0x111faf550>: Failed to establish a new connection: [Errno 8] nodename nor servname provided, or not known

During handling of the above exception, another exception occurred:

Traceback (most recent call last):
  File "/Library/Frameworks/Python.framework/Versions/3.6/lib/python3.6/site-packages/telegram/utils/request.py", line 203, in _request_wrapper
    resp = self._con_pool.request(*args, **kwargs)
  File "/Library/Frameworks/Python.framework/Versions/3.6/lib/python3.6/site-packages/telegram/vendor/ptb_urllib3/urllib3/request.py", line 70, in request
    **urlopen_kw)
  File "/Library/Frameworks/Python.framework/Versions/3.6/lib/python3.6/site-packages/telegram/vendor/ptb_urllib3/urllib3/request.py", line 148, in request_encode_body
    return self.urlopen(method, url, **extra_kw)
  File "/Library/Frameworks/Python.framework/Versions/3.6/lib/python3.6/site-packages/telegram/vendor/ptb_urllib3/urllib3/poolmanager.py", line 244, in urlopen
    response = conn.urlopen(method, u.request_uri, **kw)
  File "/Library/Frameworks/Python.framework/Versions/3.6/lib/python3.6/site-packages/telegram/vendor/ptb_urllib3/urllib3/connectionpool.py", line 695, in urlopen
    **response_kw)
  File "/Library/Frameworks/Python.framework/Versions/3.6/lib/python3.6/site-packages/telegram/vendor/ptb_urllib3/urllib3/connectionpool.py", line 695, in urlopen
    **response_kw)
  File "/Library/Frameworks/Python.framework/Versions/3.6/lib/python3.6/site-packages/telegram/vendor/ptb_urllib3/urllib3/connectionpool.py", line 695, in urlopen
    **response_kw)
  File "/Library/Frameworks/Python.framework/Versions/3.6/lib/python3.6/site-packages/telegram/vendor/ptb_urllib3/urllib3/connectionpool.py", line 666, in urlopen
    _stacktrace=sys.exc_info()[2])
  File "/Library/Frameworks/Python.framework/Versions/3.6/lib/python3.6/site-packages/telegram/vendor/ptb_urllib3/urllib3/util/retry.py", line 376, in increment
    raise MaxRetryError(_pool, url, error or ResponseError(cause))
telegram.vendor.ptb_urllib3.urllib3.exceptions.MaxRetryError: SOCKSHTTPSConnectionPool(host='api.telegram.org', port=443): Max retries exceeded with url: /bot646613110:AAEaqvqJnNUOqVNNFTmHU5mTEVxN3VJpQlo/getUpdates (Caused by NewConnectionError('<telegram.vendor.ptb_urllib3.urllib3.contrib.socks.SOCKSHTTPSConnection object at 0x111faf550>: Failed to establish a new connection: [Errno 8] nodename nor servname provided, or not known',))

During handling of the above exception, another exception occurred:

Traceback (most recent call last):
  File "/Library/Frameworks/Python.framework/Versions/3.6/lib/python3.6/site-packages/telegram/ext/updater.py", line 319, in _network_loop_retry
    if not action_cb():
  File "/Library/Frameworks/Python.framework/Versions/3.6/lib/python3.6/site-packages/telegram/ext/updater.py", line 280, in polling_action_cb
    allowed_updates=allowed_updates)
  File "/Library/Frameworks/Python.framework/Versions/3.6/lib/python3.6/site-packages/telegram/bot.py", line 65, in decorator
    result = func(self, *args, **kwargs)
  File "/Library/Frameworks/Python.framework/Versions/3.6/lib/python3.6/site-packages/telegram/bot.py", line 1975, in get_updates
    result = self._request.post(url, data, timeout=float(read_latency) + float(timeout))
  File "/Library/Frameworks/Python.framework/Versions/3.6/lib/python3.6/site-packages/telegram/utils/request.py", line 309, in post
    headers={'Content-Type': 'application/json'})
  File "/Library/Frameworks/Python.framework/Versions/3.6/lib/python3.6/site-packages/telegram/utils/request.py", line 209, in _request_wrapper
    raise NetworkError('urllib3 HTTPError {0}'.format(error))
telegram.error.NetworkError: urllib3 HTTPError SOCKSHTTPSConnectionPool(host='api.telegram.org', port=443): Max retries exceeded with url: /bot646613110:AAEaqvqJnNUOqVNNFTmHU5mTEVxN3VJpQlo/getUpdates (Caused by NewConnectionError('<telegram.vendor.ptb_urllib3.urllib3.contrib.socks.SOCKSHTTPSConnection object at 0x111faf550>: Failed to establish a new connection: [Errno 8] nodename nor servname provided, or not known',))
2018-09-15 13:30:51,887 - WARNING - Retrying (Retry(total=2, connect=None, read=None, redirect=None)) after connection broken by 'NewConnectionError('<telegram.vendor.ptb_urllib3.urllib3.contrib.socks.SOCKSHTTPSConnection object at 0x111faf5c0>: Failed to establish a new connection: [Errno 8] nodename nor servname provided, or not known',)': /bot646613110:AAEaqvqJnNUOqVNNFTmHU5mTEVxN3VJpQlo/getUpdates
2018-09-15 13:30:51,888 - WARNING - Retrying (Retry(total=1, connect=None, read=None, redirect=None)) after connection broken by 'NewConnectionError('<telegram.vendor.ptb_urllib3.urllib3.contrib.socks.SOCKSHTTPSConnection object at 0x111faf748>: Failed to establish a new connection: [Errno 8] nodename nor servname provided, or not known',)': /bot646613110:AAEaqvqJnNUOqVNNFTmHU5mTEVxN3VJpQlo/getUpdates
2018-09-15 13:30:51,889 - WARNING - Retrying (Retry(total=0, connect=None, read=None, redirect=None)) after connection broken by 'NewConnectionError('<telegram.vendor.ptb_urllib3.urllib3.contrib.socks.SOCKSHTTPSConnection object at 0x111faf828>: Failed to establish a new connection: [Errno 8] nodename nor servname provided, or not known',)': /bot646613110:AAEaqvqJnNUOqVNNFTmHU5mTEVxN3VJpQlo/getUpdates
2018-09-15 13:30:51,890 - ERROR - Error while getting Updates: urllib3 HTTPError SOCKSHTTPSConnectionPool(host='api.telegram.org', port=443): Max retries exceeded with url: /bot646613110:AAEaqvqJnNUOqVNNFTmHU5mTEVxN3VJpQlo/getUpdates (Caused by NewConnectionError('<telegram.vendor.ptb_urllib3.urllib3.contrib.socks.SOCKSHTTPSConnection object at 0x111faf908>: Failed to establish a new connection: [Errno 8] nodename nor servname provided, or not known',))
2018-09-15 13:30:51,890 - ERROR - No error handlers are registered, logging exception.
Traceback (most recent call last):
  File "/Library/Frameworks/Python.framework/Versions/3.6/lib/python3.6/site-packages/telegram/vendor/ptb_urllib3/urllib3/contrib/socks.py", line 88, in _new_conn
    **extra_kw
  File "/Library/Frameworks/Python.framework/Versions/3.6/lib/python3.6/site-packages/socks.py", line 233, in create_connection
    for r in socket.getaddrinfo(proxy_addr, proxy_port, 0, socket.SOCK_STREAM):
  File "/Library/Frameworks/Python.framework/Versions/3.6/lib/python3.6/socket.py", line 745, in getaddrinfo
    for res in _socket.getaddrinfo(host, port, family, type, proto, flags):
socket.gaierror: [Errno 8] nodename nor servname provided, or not known

During handling of the above exception, another exception occurred:

Traceback (most recent call last):
  File "/Library/Frameworks/Python.framework/Versions/3.6/lib/python3.6/site-packages/telegram/vendor/ptb_urllib3/urllib3/connectionpool.py", line 617, in urlopen
    chunked=chunked)
  File "/Library/Frameworks/Python.framework/Versions/3.6/lib/python3.6/site-packages/telegram/vendor/ptb_urllib3/urllib3/connectionpool.py", line 360, in _make_request
    self._validate_conn(conn)
  File "/Library/Frameworks/Python.framework/Versions/3.6/lib/python3.6/site-packages/telegram/vendor/ptb_urllib3/urllib3/connectionpool.py", line 857, in _validate_conn
    super(HTTPSConnectionPool, self)._validate_conn(conn)
  File "/Library/Frameworks/Python.framework/Versions/3.6/lib/python3.6/site-packages/telegram/vendor/ptb_urllib3/urllib3/connectionpool.py", line 289, in _validate_conn
    conn.connect()
  File "/Library/Frameworks/Python.framework/Versions/3.6/lib/python3.6/site-packages/telegram/vendor/ptb_urllib3/urllib3/connection.py", line 284, in connect
    conn = self._new_conn()
  File "/Library/Frameworks/Python.framework/Versions/3.6/lib/python3.6/site-packages/telegram/vendor/ptb_urllib3/urllib3/contrib/socks.py", line 120, in _new_conn
    self, "Failed to establish a new connection: %s" % e)
telegram.vendor.ptb_urllib3.urllib3.exceptions.NewConnectionError: <telegram.vendor.ptb_urllib3.urllib3.contrib.socks.SOCKSHTTPSConnection object at 0x111faf908>: Failed to establish a new connection: [Errno 8] nodename nor servname provided, or not known

During handling of the above exception, another exception occurred:

Traceback (most recent call last):
  File "/Library/Frameworks/Python.framework/Versions/3.6/lib/python3.6/site-packages/telegram/utils/request.py", line 203, in _request_wrapper
    resp = self._con_pool.request(*args, **kwargs)
  File "/Library/Frameworks/Python.framework/Versions/3.6/lib/python3.6/site-packages/telegram/vendor/ptb_urllib3/urllib3/request.py", line 70, in request
    **urlopen_kw)
  File "/Library/Frameworks/Python.framework/Versions/3.6/lib/python3.6/site-packages/telegram/vendor/ptb_urllib3/urllib3/request.py", line 148, in request_encode_body
    return self.urlopen(method, url, **extra_kw)
  File "/Library/Frameworks/Python.framework/Versions/3.6/lib/python3.6/site-packages/telegram/vendor/ptb_urllib3/urllib3/poolmanager.py", line 244, in urlopen
    response = conn.urlopen(method, u.request_uri, **kw)
  File "/Library/Frameworks/Python.framework/Versions/3.6/lib/python3.6/site-packages/telegram/vendor/ptb_urllib3/urllib3/connectionpool.py", line 695, in urlopen
    **response_kw)
  File "/Library/Frameworks/Python.framework/Versions/3.6/lib/python3.6/site-packages/telegram/vendor/ptb_urllib3/urllib3/connectionpool.py", line 695, in urlopen
    **response_kw)
  File "/Library/Frameworks/Python.framework/Versions/3.6/lib/python3.6/site-packages/telegram/vendor/ptb_urllib3/urllib3/connectionpool.py", line 695, in urlopen
    **response_kw)
  File "/Library/Frameworks/Python.framework/Versions/3.6/lib/python3.6/site-packages/telegram/vendor/ptb_urllib3/urllib3/connectionpool.py", line 666, in urlopen
    _stacktrace=sys.exc_info()[2])
  File "/Library/Frameworks/Python.framework/Versions/3.6/lib/python3.6/site-packages/telegram/vendor/ptb_urllib3/urllib3/util/retry.py", line 376, in increment
    raise MaxRetryError(_pool, url, error or ResponseError(cause))
telegram.vendor.ptb_urllib3.urllib3.exceptions.MaxRetryError: SOCKSHTTPSConnectionPool(host='api.telegram.org', port=443): Max retries exceeded with url: /bot646613110:AAEaqvqJnNUOqVNNFTmHU5mTEVxN3VJpQlo/getUpdates (Caused by NewConnectionError('<telegram.vendor.ptb_urllib3.urllib3.contrib.socks.SOCKSHTTPSConnection object at 0x111faf908>: Failed to establish a new connection: [Errno 8] nodename nor servname provided, or not known',))

During handling of the above exception, another exception occurred:

Traceback (most recent call last):
  File "/Library/Frameworks/Python.framework/Versions/3.6/lib/python3.6/site-packages/telegram/ext/updater.py", line 319, in _network_loop_retry
    if not action_cb():
  File "/Library/Frameworks/Python.framework/Versions/3.6/lib/python3.6/site-packages/telegram/ext/updater.py", line 280, in polling_action_cb
    allowed_updates=allowed_updates)
  File "/Library/Frameworks/Python.framework/Versions/3.6/lib/python3.6/site-packages/telegram/bot.py", line 65, in decorator
    result = func(self, *args, **kwargs)
  File "/Library/Frameworks/Python.framework/Versions/3.6/lib/python3.6/site-packages/telegram/bot.py", line 1975, in get_updates
    result = self._request.post(url, data, timeout=float(read_latency) + float(timeout))
  File "/Library/Frameworks/Python.framework/Versions/3.6/lib/python3.6/site-packages/telegram/utils/request.py", line 309, in post
    headers={'Content-Type': 'application/json'})
  File "/Library/Frameworks/Python.framework/Versions/3.6/lib/python3.6/site-packages/telegram/utils/request.py", line 209, in _request_wrapper
    raise NetworkError('urllib3 HTTPError {0}'.format(error))
telegram.error.NetworkError: urllib3 HTTPError SOCKSHTTPSConnectionPool(host='api.telegram.org', port=443): Max retries exceeded with url: /bot646613110:AAEaqvqJnNUOqVNNFTmHU5mTEVxN3VJpQlo/getUpdates (Caused by NewConnectionError('<telegram.vendor.ptb_urllib3.urllib3.contrib.socks.SOCKSHTTPSConnection object at 0x111faf908>: Failed to establish a new connection: [Errno 8] nodename nor servname provided, or not known',))
2018-09-15 14:37:49,723 - WARNING - Retrying (Retry(total=2, connect=None, read=None, redirect=None)) after connection broken by 'NewConnectionError('<telegram.vendor.ptb_urllib3.urllib3.contrib.socks.SOCKSHTTPSConnection object at 0x111faf5f8>: Failed to establish a new connection: [Errno 8] nodename nor servname provided, or not known',)': /bot646613110:AAEaqvqJnNUOqVNNFTmHU5mTEVxN3VJpQlo/getUpdates
2018-09-15 14:37:49,725 - WARNING - Retrying (Retry(total=1, connect=None, read=None, redirect=None)) after connection broken by 'NewConnectionError('<telegram.vendor.ptb_urllib3.urllib3.contrib.socks.SOCKSHTTPSConnection object at 0x111fafb00>: Failed to establish a new connection: [Errno 8] nodename nor servname provided, or not known',)': /bot646613110:AAEaqvqJnNUOqVNNFTmHU5mTEVxN3VJpQlo/getUpdates
2018-09-15 14:37:49,727 - WARNING - Retrying (Retry(total=0, connect=None, read=None, redirect=None)) after connection broken by 'NewConnectionError('<telegram.vendor.ptb_urllib3.urllib3.contrib.socks.SOCKSHTTPSConnection object at 0x111fafbe0>: Failed to establish a new connection: [Errno 8] nodename nor servname provided, or not known',)': /bot646613110:AAEaqvqJnNUOqVNNFTmHU5mTEVxN3VJpQlo/getUpdates
2018-09-15 14:37:49,729 - ERROR - Error while getting Updates: urllib3 HTTPError SOCKSHTTPSConnectionPool(host='api.telegram.org', port=443): Max retries exceeded with url: /bot646613110:AAEaqvqJnNUOqVNNFTmHU5mTEVxN3VJpQlo/getUpdates (Caused by NewConnectionError('<telegram.vendor.ptb_urllib3.urllib3.contrib.socks.SOCKSHTTPSConnection object at 0x111fafcc0>: Failed to establish a new connection: [Errno 8] nodename nor servname provided, or not known',))
2018-09-15 14:37:49,729 - ERROR - No error handlers are registered, logging exception.
Traceback (most recent call last):
  File "/Library/Frameworks/Python.framework/Versions/3.6/lib/python3.6/site-packages/telegram/vendor/ptb_urllib3/urllib3/contrib/socks.py", line 88, in _new_conn
    **extra_kw
  File "/Library/Frameworks/Python.framework/Versions/3.6/lib/python3.6/site-packages/socks.py", line 233, in create_connection
    for r in socket.getaddrinfo(proxy_addr, proxy_port, 0, socket.SOCK_STREAM):
  File "/Library/Frameworks/Python.framework/Versions/3.6/lib/python3.6/socket.py", line 745, in getaddrinfo
    for res in _socket.getaddrinfo(host, port, family, type, proto, flags):
socket.gaierror: [Errno 8] nodename nor servname provided, or not known

During handling of the above exception, another exception occurred:

Traceback (most recent call last):
  File "/Library/Frameworks/Python.framework/Versions/3.6/lib/python3.6/site-packages/telegram/vendor/ptb_urllib3/urllib3/connectionpool.py", line 617, in urlopen
    chunked=chunked)
  File "/Library/Frameworks/Python.framework/Versions/3.6/lib/python3.6/site-packages/telegram/vendor/ptb_urllib3/urllib3/connectionpool.py", line 360, in _make_request
    self._validate_conn(conn)
  File "/Library/Frameworks/Python.framework/Versions/3.6/lib/python3.6/site-packages/telegram/vendor/ptb_urllib3/urllib3/connectionpool.py", line 857, in _validate_conn
    super(HTTPSConnectionPool, self)._validate_conn(conn)
  File "/Library/Frameworks/Python.framework/Versions/3.6/lib/python3.6/site-packages/telegram/vendor/ptb_urllib3/urllib3/connectionpool.py", line 289, in _validate_conn
    conn.connect()
  File "/Library/Frameworks/Python.framework/Versions/3.6/lib/python3.6/site-packages/telegram/vendor/ptb_urllib3/urllib3/connection.py", line 284, in connect
    conn = self._new_conn()
  File "/Library/Frameworks/Python.framework/Versions/3.6/lib/python3.6/site-packages/telegram/vendor/ptb_urllib3/urllib3/contrib/socks.py", line 120, in _new_conn
    self, "Failed to establish a new connection: %s" % e)
telegram.vendor.ptb_urllib3.urllib3.exceptions.NewConnectionError: <telegram.vendor.ptb_urllib3.urllib3.contrib.socks.SOCKSHTTPSConnection object at 0x111fafcc0>: Failed to establish a new connection: [Errno 8] nodename nor servname provided, or not known

During handling of the above exception, another exception occurred:

Traceback (most recent call last):
  File "/Library/Frameworks/Python.framework/Versions/3.6/lib/python3.6/site-packages/telegram/utils/request.py", line 203, in _request_wrapper
    resp = self._con_pool.request(*args, **kwargs)
  File "/Library/Frameworks/Python.framework/Versions/3.6/lib/python3.6/site-packages/telegram/vendor/ptb_urllib3/urllib3/request.py", line 70, in request
    **urlopen_kw)
  File "/Library/Frameworks/Python.framework/Versions/3.6/lib/python3.6/site-packages/telegram/vendor/ptb_urllib3/urllib3/request.py", line 148, in request_encode_body
    return self.urlopen(method, url, **extra_kw)
  File "/Library/Frameworks/Python.framework/Versions/3.6/lib/python3.6/site-packages/telegram/vendor/ptb_urllib3/urllib3/poolmanager.py", line 244, in urlopen
    response = conn.urlopen(method, u.request_uri, **kw)
  File "/Library/Frameworks/Python.framework/Versions/3.6/lib/python3.6/site-packages/telegram/vendor/ptb_urllib3/urllib3/connectionpool.py", line 695, in urlopen
    **response_kw)
  File "/Library/Frameworks/Python.framework/Versions/3.6/lib/python3.6/site-packages/telegram/vendor/ptb_urllib3/urllib3/connectionpool.py", line 695, in urlopen
    **response_kw)
  File "/Library/Frameworks/Python.framework/Versions/3.6/lib/python3.6/site-packages/telegram/vendor/ptb_urllib3/urllib3/connectionpool.py", line 695, in urlopen
    **response_kw)
  File "/Library/Frameworks/Python.framework/Versions/3.6/lib/python3.6/site-packages/telegram/vendor/ptb_urllib3/urllib3/connectionpool.py", line 666, in urlopen
    _stacktrace=sys.exc_info()[2])
  File "/Library/Frameworks/Python.framework/Versions/3.6/lib/python3.6/site-packages/telegram/vendor/ptb_urllib3/urllib3/util/retry.py", line 376, in increment
    raise MaxRetryError(_pool, url, error or ResponseError(cause))
telegram.vendor.ptb_urllib3.urllib3.exceptions.MaxRetryError: SOCKSHTTPSConnectionPool(host='api.telegram.org', port=443): Max retries exceeded with url: /bot646613110:AAEaqvqJnNUOqVNNFTmHU5mTEVxN3VJpQlo/getUpdates (Caused by NewConnectionError('<telegram.vendor.ptb_urllib3.urllib3.contrib.socks.SOCKSHTTPSConnection object at 0x111fafcc0>: Failed to establish a new connection: [Errno 8] nodename nor servname provided, or not known',))

During handling of the above exception, another exception occurred:

Traceback (most recent call last):
  File "/Library/Frameworks/Python.framework/Versions/3.6/lib/python3.6/site-packages/telegram/ext/updater.py", line 319, in _network_loop_retry
    if not action_cb():
  File "/Library/Frameworks/Python.framework/Versions/3.6/lib/python3.6/site-packages/telegram/ext/updater.py", line 280, in polling_action_cb
    allowed_updates=allowed_updates)
  File "/Library/Frameworks/Python.framework/Versions/3.6/lib/python3.6/site-packages/telegram/bot.py", line 65, in decorator
    result = func(self, *args, **kwargs)
  File "/Library/Frameworks/Python.framework/Versions/3.6/lib/python3.6/site-packages/telegram/bot.py", line 1975, in get_updates
    result = self._request.post(url, data, timeout=float(read_latency) + float(timeout))
  File "/Library/Frameworks/Python.framework/Versions/3.6/lib/python3.6/site-packages/telegram/utils/request.py", line 309, in post
    headers={'Content-Type': 'application/json'})
  File "/Library/Frameworks/Python.framework/Versions/3.6/lib/python3.6/site-packages/telegram/utils/request.py", line 209, in _request_wrapper
    raise NetworkError('urllib3 HTTPError {0}'.format(error))
telegram.error.NetworkError: urllib3 HTTPError SOCKSHTTPSConnectionPool(host='api.telegram.org', port=443): Max retries exceeded with url: /bot646613110:AAEaqvqJnNUOqVNNFTmHU5mTEVxN3VJpQlo/getUpdates (Caused by NewConnectionError('<telegram.vendor.ptb_urllib3.urllib3.contrib.socks.SOCKSHTTPSConnection object at 0x111fafcc0>: Failed to establish a new connection: [Errno 8] nodename nor servname provided, or not known',))
2018-09-15 14:37:57,330 - WARNING - Retrying (Retry(total=2, connect=None, read=None, redirect=None)) after connection broken by 'NewConnectionError('<telegram.vendor.ptb_urllib3.urllib3.contrib.socks.SOCKSHTTPSConnection object at 0x111faf588>: Failed to establish a new connection: [Errno 8] nodename nor servname provided, or not known',)': /bot646613110:AAEaqvqJnNUOqVNNFTmHU5mTEVxN3VJpQlo/getUpdates
2018-09-15 14:37:57,332 - WARNING - Retrying (Retry(total=1, connect=None, read=None, redirect=None)) after connection broken by 'NewConnectionError('<telegram.vendor.ptb_urllib3.urllib3.contrib.socks.SOCKSHTTPSConnection object at 0x111fafeb8>: Failed to establish a new connection: [Errno 8] nodename nor servname provided, or not known',)': /bot646613110:AAEaqvqJnNUOqVNNFTmHU5mTEVxN3VJpQlo/getUpdates
2018-09-15 14:37:57,334 - WARNING - Retrying (Retry(total=0, connect=None, read=None, redirect=None)) after connection broken by 'NewConnectionError('<telegram.vendor.ptb_urllib3.urllib3.contrib.socks.SOCKSHTTPSConnection object at 0x111faff98>: Failed to establish a new connection: [Errno 8] nodename nor servname provided, or not known',)': /bot646613110:AAEaqvqJnNUOqVNNFTmHU5mTEVxN3VJpQlo/getUpdates
2018-09-15 14:37:57,336 - ERROR - Error while getting Updates: urllib3 HTTPError SOCKSHTTPSConnectionPool(host='api.telegram.org', port=443): Max retries exceeded with url: /bot646613110:AAEaqvqJnNUOqVNNFTmHU5mTEVxN3VJpQlo/getUpdates (Caused by NewConnectionError('<telegram.vendor.ptb_urllib3.urllib3.contrib.socks.SOCKSHTTPSConnection object at 0x111faf828>: Failed to establish a new connection: [Errno 8] nodename nor servname provided, or not known',))
2018-09-15 14:37:57,336 - ERROR - No error handlers are registered, logging exception.
Traceback (most recent call last):
  File "/Library/Frameworks/Python.framework/Versions/3.6/lib/python3.6/site-packages/telegram/vendor/ptb_urllib3/urllib3/contrib/socks.py", line 88, in _new_conn
    **extra_kw
  File "/Library/Frameworks/Python.framework/Versions/3.6/lib/python3.6/site-packages/socks.py", line 233, in create_connection
    for r in socket.getaddrinfo(proxy_addr, proxy_port, 0, socket.SOCK_STREAM):
  File "/Library/Frameworks/Python.framework/Versions/3.6/lib/python3.6/socket.py", line 745, in getaddrinfo
    for res in _socket.getaddrinfo(host, port, family, type, proto, flags):
socket.gaierror: [Errno 8] nodename nor servname provided, or not known

During handling of the above exception, another exception occurred:

Traceback (most recent call last):
  File "/Library/Frameworks/Python.framework/Versions/3.6/lib/python3.6/site-packages/telegram/vendor/ptb_urllib3/urllib3/connectionpool.py", line 617, in urlopen
    chunked=chunked)
  File "/Library/Frameworks/Python.framework/Versions/3.6/lib/python3.6/site-packages/telegram/vendor/ptb_urllib3/urllib3/connectionpool.py", line 360, in _make_request
    self._validate_conn(conn)
  File "/Library/Frameworks/Python.framework/Versions/3.6/lib/python3.6/site-packages/telegram/vendor/ptb_urllib3/urllib3/connectionpool.py", line 857, in _validate_conn
    super(HTTPSConnectionPool, self)._validate_conn(conn)
  File "/Library/Frameworks/Python.framework/Versions/3.6/lib/python3.6/site-packages/telegram/vendor/ptb_urllib3/urllib3/connectionpool.py", line 289, in _validate_conn
    conn.connect()
  File "/Library/Frameworks/Python.framework/Versions/3.6/lib/python3.6/site-packages/telegram/vendor/ptb_urllib3/urllib3/connection.py", line 284, in connect
    conn = self._new_conn()
  File "/Library/Frameworks/Python.framework/Versions/3.6/lib/python3.6/site-packages/telegram/vendor/ptb_urllib3/urllib3/contrib/socks.py", line 120, in _new_conn
    self, "Failed to establish a new connection: %s" % e)
telegram.vendor.ptb_urllib3.urllib3.exceptions.NewConnectionError: <telegram.vendor.ptb_urllib3.urllib3.contrib.socks.SOCKSHTTPSConnection object at 0x111faf828>: Failed to establish a new connection: [Errno 8] nodename nor servname provided, or not known

During handling of the above exception, another exception occurred:

Traceback (most recent call last):
  File "/Library/Frameworks/Python.framework/Versions/3.6/lib/python3.6/site-packages/telegram/utils/request.py", line 203, in _request_wrapper
    resp = self._con_pool.request(*args, **kwargs)
  File "/Library/Frameworks/Python.framework/Versions/3.6/lib/python3.6/site-packages/telegram/vendor/ptb_urllib3/urllib3/request.py", line 70, in request
    **urlopen_kw)
  File "/Library/Frameworks/Python.framework/Versions/3.6/lib/python3.6/site-packages/telegram/vendor/ptb_urllib3/urllib3/request.py", line 148, in request_encode_body
    return self.urlopen(method, url, **extra_kw)
  File "/Library/Frameworks/Python.framework/Versions/3.6/lib/python3.6/site-packages/telegram/vendor/ptb_urllib3/urllib3/poolmanager.py", line 244, in urlopen
    response = conn.urlopen(method, u.request_uri, **kw)
  File "/Library/Frameworks/Python.framework/Versions/3.6/lib/python3.6/site-packages/telegram/vendor/ptb_urllib3/urllib3/connectionpool.py", line 695, in urlopen
    **response_kw)
  File "/Library/Frameworks/Python.framework/Versions/3.6/lib/python3.6/site-packages/telegram/vendor/ptb_urllib3/urllib3/connectionpool.py", line 695, in urlopen
    **response_kw)
  File "/Library/Frameworks/Python.framework/Versions/3.6/lib/python3.6/site-packages/telegram/vendor/ptb_urllib3/urllib3/connectionpool.py", line 695, in urlopen
    **response_kw)
  File "/Library/Frameworks/Python.framework/Versions/3.6/lib/python3.6/site-packages/telegram/vendor/ptb_urllib3/urllib3/connectionpool.py", line 666, in urlopen
    _stacktrace=sys.exc_info()[2])
  File "/Library/Frameworks/Python.framework/Versions/3.6/lib/python3.6/site-packages/telegram/vendor/ptb_urllib3/urllib3/util/retry.py", line 376, in increment
    raise MaxRetryError(_pool, url, error or ResponseError(cause))
telegram.vendor.ptb_urllib3.urllib3.exceptions.MaxRetryError: SOCKSHTTPSConnectionPool(host='api.telegram.org', port=443): Max retries exceeded with url: /bot646613110:AAEaqvqJnNUOqVNNFTmHU5mTEVxN3VJpQlo/getUpdates (Caused by NewConnectionError('<telegram.vendor.ptb_urllib3.urllib3.contrib.socks.SOCKSHTTPSConnection object at 0x111faf828>: Failed to establish a new connection: [Errno 8] nodename nor servname provided, or not known',))

During handling of the above exception, another exception occurred:

Traceback (most recent call last):
  File "/Library/Frameworks/Python.framework/Versions/3.6/lib/python3.6/site-packages/telegram/ext/updater.py", line 319, in _network_loop_retry
    if not action_cb():
  File "/Library/Frameworks/Python.framework/Versions/3.6/lib/python3.6/site-packages/telegram/ext/updater.py", line 280, in polling_action_cb
    allowed_updates=allowed_updates)
  File "/Library/Frameworks/Python.framework/Versions/3.6/lib/python3.6/site-packages/telegram/bot.py", line 65, in decorator
    result = func(self, *args, **kwargs)
  File "/Library/Frameworks/Python.framework/Versions/3.6/lib/python3.6/site-packages/telegram/bot.py", line 1975, in get_updates
    result = self._request.post(url, data, timeout=float(read_latency) + float(timeout))
  File "/Library/Frameworks/Python.framework/Versions/3.6/lib/python3.6/site-packages/telegram/utils/request.py", line 309, in post
    headers={'Content-Type': 'application/json'})
  File "/Library/Frameworks/Python.framework/Versions/3.6/lib/python3.6/site-packages/telegram/utils/request.py", line 209, in _request_wrapper
    raise NetworkError('urllib3 HTTPError {0}'.format(error))
telegram.error.NetworkError: urllib3 HTTPError SOCKSHTTPSConnectionPool(host='api.telegram.org', port=443): Max retries exceeded with url: /bot646613110:AAEaqvqJnNUOqVNNFTmHU5mTEVxN3VJpQlo/getUpdates (Caused by NewConnectionError('<telegram.vendor.ptb_urllib3.urllib3.contrib.socks.SOCKSHTTPSConnection object at 0x111faf828>: Failed to establish a new connection: [Errno 8] nodename nor servname provided, or not known',))
2018-09-15 14:48:10,702 - INFO - Received signal 2 (SIGINT), stopping...
2018-09-15 14:49:27,280 - INFO - Бот запускается
2018-09-15 14:49:36,185 - ERROR - An uncaught error was raised while processing the update
Traceback (most recent call last):
  File "/Library/Frameworks/Python.framework/Versions/3.6/lib/python3.6/site-packages/telegram/ext/dispatcher.py", line 279, in process_update
    handler.handle_update(update, self)
  File "/Library/Frameworks/Python.framework/Versions/3.6/lib/python3.6/site-packages/telegram/ext/commandhandler.py", line 173, in handle_update
    return self.callback(dispatcher.bot, update, **optional_args)
  File "bot_ephem.py", line 43, in planet_ephem
    constellation.split(" ")[1])
AttributeError: 'tuple' object has no attribute 'split'
2018-09-15 14:50:18,032 - INFO - Received signal 2 (SIGINT), stopping...
2018-09-15 14:50:21,869 - INFO - Бот запускается
2018-09-15 14:50:34,707 - ERROR - An uncaught error was raised while processing the update
Traceback (most recent call last):
  File "/Library/Frameworks/Python.framework/Versions/3.6/lib/python3.6/site-packages/telegram/ext/dispatcher.py", line 279, in process_update
    handler.handle_update(update, self)
  File "/Library/Frameworks/Python.framework/Versions/3.6/lib/python3.6/site-packages/telegram/ext/commandhandler.py", line 173, in handle_update
    return self.callback(dispatcher.bot, update, **optional_args)
  File "bot_ephem.py", line 41, in planet_ephem
    constellation = ephem.constellation(result).split(" ")[1]
AttributeError: 'tuple' object has no attribute 'split'
2018-09-15 14:51:04,282 - INFO - Received signal 2 (SIGINT), stopping...
2018-09-15 14:51:08,042 - INFO - Бот запускается
2018-09-15 14:51:26,346 - INFO - Вызван /start
2018-09-15 14:51:34,749 - ERROR - An uncaught error was raised while processing the update
Traceback (most recent call last):
  File "/Library/Frameworks/Python.framework/Versions/3.6/lib/python3.6/site-packages/telegram/ext/dispatcher.py", line 279, in process_update
    handler.handle_update(update, self)
  File "/Library/Frameworks/Python.framework/Versions/3.6/lib/python3.6/site-packages/telegram/ext/commandhandler.py", line 173, in handle_update
    return self.callback(dispatcher.bot, update, **optional_args)
  File "bot_ephem.py", line 44, in planet_ephem
    update.message.reply_text(constellation)
  File "/Library/Frameworks/Python.framework/Versions/3.6/lib/python3.6/site-packages/telegram/message.py", line 455, in reply_text
    return self.bot.send_message(self.chat_id, *args, **kwargs)
  File "/Library/Frameworks/Python.framework/Versions/3.6/lib/python3.6/site-packages/telegram/bot.py", line 65, in decorator
    result = func(self, *args, **kwargs)
  File "/Library/Frameworks/Python.framework/Versions/3.6/lib/python3.6/site-packages/telegram/bot.py", line 90, in decorator
    result = self._request.post(url, data, timeout=kwargs.get('timeout'))
  File "/Library/Frameworks/Python.framework/Versions/3.6/lib/python3.6/site-packages/telegram/utils/request.py", line 308, in post
    body=json.dumps(data).encode('utf-8'),
  File "/Library/Frameworks/Python.framework/Versions/3.6/lib/python3.6/json/__init__.py", line 231, in dumps
    return _default_encoder.encode(obj)
  File "/Library/Frameworks/Python.framework/Versions/3.6/lib/python3.6/json/encoder.py", line 199, in encode
    chunks = self.iterencode(o, _one_shot=True)
  File "/Library/Frameworks/Python.framework/Versions/3.6/lib/python3.6/json/encoder.py", line 257, in iterencode
    return _iterencode(o, 0)
  File "/Library/Frameworks/Python.framework/Versions/3.6/lib/python3.6/json/encoder.py", line 180, in default
    o.__class__.__name__)
TypeError: Object of type 'builtin_function_or_method' is not JSON serializable
2018-09-15 14:51:53,943 - INFO - Received signal 2 (SIGINT), stopping...
2018-09-15 14:52:08,237 - INFO - Бот запускается
2018-09-15 14:52:21,333 - ERROR - An uncaught error was raised while processing the update
Traceback (most recent call last):
  File "/Library/Frameworks/Python.framework/Versions/3.6/lib/python3.6/site-packages/telegram/ext/dispatcher.py", line 279, in process_update
    handler.handle_update(update, self)
  File "/Library/Frameworks/Python.framework/Versions/3.6/lib/python3.6/site-packages/telegram/ext/commandhandler.py", line 173, in handle_update
    return self.callback(dispatcher.bot, update, **optional_args)
  File "bot_ephem.py", line 42, in planet_ephem
    update.message.reply_text(constellation)
  File "/Library/Frameworks/Python.framework/Versions/3.6/lib/python3.6/site-packages/telegram/message.py", line 455, in reply_text
    return self.bot.send_message(self.chat_id, *args, **kwargs)
  File "/Library/Frameworks/Python.framework/Versions/3.6/lib/python3.6/site-packages/telegram/bot.py", line 65, in decorator
    result = func(self, *args, **kwargs)
  File "/Library/Frameworks/Python.framework/Versions/3.6/lib/python3.6/site-packages/telegram/bot.py", line 90, in decorator
    result = self._request.post(url, data, timeout=kwargs.get('timeout'))
  File "/Library/Frameworks/Python.framework/Versions/3.6/lib/python3.6/site-packages/telegram/utils/request.py", line 308, in post
    body=json.dumps(data).encode('utf-8'),
  File "/Library/Frameworks/Python.framework/Versions/3.6/lib/python3.6/json/__init__.py", line 231, in dumps
    return _default_encoder.encode(obj)
  File "/Library/Frameworks/Python.framework/Versions/3.6/lib/python3.6/json/encoder.py", line 199, in encode
    chunks = self.iterencode(o, _one_shot=True)
  File "/Library/Frameworks/Python.framework/Versions/3.6/lib/python3.6/json/encoder.py", line 257, in iterencode
    return _iterencode(o, 0)
  File "/Library/Frameworks/Python.framework/Versions/3.6/lib/python3.6/json/encoder.py", line 180, in default
    o.__class__.__name__)
TypeError: Object of type 'builtin_function_or_method' is not JSON serializable
2018-09-15 14:52:57,996 - INFO - Received signal 2 (SIGINT), stopping...
2018-09-15 14:53:09,296 - INFO - Бот запускается
2018-09-15 14:53:46,844 - INFO - Received signal 2 (SIGINT), stopping...
2018-09-15 15:00:30,659 - INFO - Бот запускается
2018-09-15 15:03:19,078 - INFO - Received signal 2 (SIGINT), stopping...
2018-09-15 15:08:26,418 - INFO - Бот запускается
2018-09-15 15:09:25,108 - INFO - Received signal 2 (SIGINT), stopping...
2018-09-15 15:09:38,331 - INFO - Бот запускается
2018-09-15 15:10:49,895 - INFO - Received signal 2 (SIGINT), stopping...
2018-09-15 15:10:53,608 - INFO - Бот запускается
2018-09-15 15:11:52,949 - INFO - Received signal 2 (SIGINT), stopping...
2018-09-15 15:11:57,820 - INFO - Бот запускается
2018-09-15 15:12:18,129 - INFO - Received signal 2 (SIGINT), stopping...
